<?xml version='1.0' encoding='UTF-8'?>
<sdf version="1.6">
  <model name=@model_name>
    <pose>0 0 0 0 0 0</pose>

    <!-- BlueROV2 thruster reference: http://www.ardusub.com/introduction/features.html -->

    <link name="base_link">
      <inertial>
        <pose>@center_of_mass_x @center_of_mass_y @center_of_mass_z 0 0 0</pose>
        <mass>@mass</mass>
        <inertia>
          <ixx>@ixx</ixx>
          <ixy>0</ixy>
          <ixz>0</ixz>
          <iyy>@iyy</iyy>
          <iyz>0</iyz>
          <izz>@izz</izz>
        </inertia>
      </inertial>

      <visual name="base_link_visual">
        <geometry>
          <mesh>
            <uri>model://bluerov2_heavy/meshes/bluerov2_heavy.dae</uri>
            <scale>0.025 0.025 0.025</scale>
          </mesh>
        </geometry>
      </visual>

      <!-- Collision volume * fluid_density == displaced mass, used by BuoyancyPlugin -->
      <collision name="base_link_collision">
        <pose>@center_of_volume_x @center_of_volume_y @center_of_volume_z 0 0 0</pose>
        <geometry>
          <box>
            <size>@collision_x @collision_y @collision_z</size>
          </box>
        </geometry>
      </collision>

      <!-- IMU sensor gyro and accel data will be sent to ArduSub -->
      <sensor name="imu_sensor" type="imu">
        <!-- Transform from the Gazebo body frame (x-forward, y-left, z-up)
             to the ArduPilot body frame (x-forward, y-right, z-down) -->
        <pose>0 0 0 @d180 0 0</pose>
        <always_on>1</always_on>
        <update_rate>1000.0</update_rate>
      </sensor>

    </link>

    <!-- Hydrodynamics plugin -->
    <plugin
        filename="gz-sim-hydrodynamics-system"
        name="gz::sim::systems::Hydrodynamics">
      <link_name>base_link</link_name>
      <water_density>@fluid_density</water_density>
      <!-- Added mass: -->
      <xDotU>@xDotU</xDotU>
      <yDotV>@yDotV</yDotV>
      <zDotW>@zDotW</zDotW>
      <kDotP>@kDotP</kDotP>
      <mDotQ>@mDotQ</mDotQ>
      <nDotR>@nDotR</nDotR>
      <!-- First order stability derivative: -->
      <xU>@xU</xU>
      <yV>@yV</yV>
      <zW>@zW</zW>
      <kP>@kP</kP>
      <mQ>@mQ</mQ>
      <nR>@nR</nR>
      <!-- Second order stability derivative: -->
      <xUabsU>@xUabsU</xUabsU>
      <yVabsV>@yVabsV</yVabsV>
      <zWabsW>@zWabsW</zWabsW>
      <kPabsP>@kPabsP</kPabsP>
      <mQabsQ>@mQabsQ</mQabsQ>
      <nRabsR>@nRabsR</nRabsR>
    </plugin>

    <link name="thruster1">
      <pose>@thruster1_x @thruster1_y @thruster1_z -@d90 @d90 -@d45</pose>
      <visual name="thruster_prop_visual">
        <pose>0 0 0 -@d90 0 0</pose>
        <geometry>
          <mesh>
            <uri>model://bluerov2_heavy/meshes/t200_ccw_prop.dae</uri>
          </mesh>
        </geometry>
      </visual>
      <inertial>
        <mass>@propeller_mass</mass>
        <inertia>
          <ixx>@propeller_ixx</ixx>
          <ixy>0</ixy>
          <ixz>0</ixz>
          <iyy>@propeller_iyy</iyy>
          <iyz>0</iyz>
          <izz>@propeller_izz</izz>
        </inertia>
      </inertial>
    </link>

    <link name="thruster2">
      <pose>@thruster2_x @thruster2_y @thruster2_z -@d90 @d90 -@d135</pose>
      <visual name="thruster_prop_visual">
        <pose>0 0 0 -@d90 0 0</pose>
        <geometry>
          <mesh>
            <uri>model://bluerov2_heavy/meshes/t200_ccw_prop.dae</uri>
          </mesh>
        </geometry>
      </visual>
      <inertial>
        <mass>@propeller_mass</mass>
        <inertia>
          <ixx>@propeller_ixx</ixx>
          <ixy>0</ixy>
          <ixz>0</ixz>
          <iyy>@propeller_iyy</iyy>
          <iyz>0</iyz>
          <izz>@propeller_izz</izz>
        </inertia>
      </inertial>
    </link>

    <link name="thruster3">
      <pose>@thruster3_x @thruster3_y @thruster3_z -@d90 @d90 @d45</pose>
      <visual name="thruster_prop_visual">
        <pose>0 0 0 @d90 0 0</pose>
        <geometry>
          <mesh>
            <uri>model://bluerov2_heavy/meshes/t200_cw_prop.dae</uri>
          </mesh>
        </geometry>
      </visual>
      <inertial>
        <mass>@propeller_mass</mass>
        <inertia>
          <ixx>@propeller_ixx</ixx>
          <ixy>0</ixy>
          <ixz>0</ixz>
          <iyy>@propeller_iyy</iyy>
          <iyz>0</iyz>
          <izz>@propeller_izz</izz>
        </inertia>
      </inertial>
    </link>

    <link name="thruster4">
      <pose>@thruster4_x @thruster4_y @thruster4_z -@d90 @d90 @d135</pose>
      <visual name="thruster_prop_visual">
        <pose>0 0 0 @d90 0 0</pose>
        <geometry>
          <mesh>
            <uri>model://bluerov2_heavy/meshes/t200_cw_prop.dae</uri>
          </mesh>
        </geometry>
      </visual>
      <inertial>
        <mass>@propeller_mass</mass>
        <inertia>
          <ixx>@propeller_ixx</ixx>
          <ixy>0</ixy>
          <ixz>0</ixz>
          <iyy>@propeller_iyy</iyy>
          <iyz>0</iyz>
          <izz>@propeller_izz</izz>
        </inertia>
      </inertial>
    </link>

    <link name="thruster5">
      <pose>@thruster5_x @thruster5_y @thruster5_z 0 0 0</pose>
      <visual name="thruster_prop_visual">
        <pose>0 0 0 -@d90 0 @d90</pose>
        <geometry>
          <mesh>
            <uri>model://bluerov2_heavy/meshes/t200_ccw_prop.dae</uri>
          </mesh>
        </geometry>
      </visual>
      <inertial>
        <mass>@propeller_mass</mass>
        <inertia>
          <ixx>@propeller_ixx</ixx>
          <ixy>0</ixy>
          <ixz>0</ixz>
          <iyy>@propeller_iyy</iyy>
          <iyz>0</iyz>
          <izz>@propeller_izz</izz>
        </inertia>
      </inertial>
    </link>

    <link name="thruster6">
      <pose>@thruster6_x @thruster6_y @thruster6_z 0 0 0</pose>
      <visual name="thruster_prop_visual">
        <pose>0 0 0 @d90 0 @d90</pose>
        <geometry>
          <mesh>
            <uri>model://bluerov2_heavy/meshes/t200_cw_prop.dae</uri>
          </mesh>
        </geometry>
      </visual>
      <inertial>
        <mass>@propeller_mass</mass>
        <inertia>
          <ixx>@propeller_ixx</ixx>
          <ixy>0</ixy>
          <ixz>0</ixz>
          <iyy>@propeller_iyy</iyy>
          <iyz>0</iyz>
          <izz>@propeller_izz</izz>
        </inertia>
      </inertial>
    </link>

    <link name="thruster7">
      <pose>@thruster7_x @thruster7_y @thruster7_z 0 0 0</pose>
      <visual name="thruster_prop_visual">
        <pose>0 0 0 @d90 0 @d90</pose>
        <geometry>
          <mesh>
            <uri>model://bluerov2_heavy/meshes/t200_cw_prop.dae</uri>
          </mesh>
        </geometry>
      </visual>
      <inertial>
        <mass>@propeller_mass</mass>
        <inertia>
          <ixx>@propeller_ixx</ixx>
          <ixy>0</ixy>
          <ixz>0</ixz>
          <iyy>@propeller_iyy</iyy>
          <iyz>0</iyz>
          <izz>@propeller_izz</izz>
        </inertia>
      </inertial>
    </link>

    <link name="thruster8">
      <pose>@thruster8_x @thruster8_y @thruster8_z 0 0 0</pose>
      <visual name="thruster_prop_visual">
        <pose>0 0 0 -@d90 0 @d90</pose>
        <geometry>
          <mesh>
            <uri>model://bluerov2_heavy/meshes/t200_ccw_prop.dae</uri>
          </mesh>
        </geometry>
      </visual>
      <inertial>
        <mass>@propeller_mass</mass>
        <inertia>
          <ixx>@propeller_ixx</ixx>
          <ixy>0</ixy>
          <ixz>0</ixz>
          <iyy>@propeller_iyy</iyy>
          <iyz>0</iyz>
          <izz>@propeller_izz</izz>
        </inertia>
      </inertial>
    </link>

    <joint name="thruster1_joint" type="revolute">
      <parent>base_link</parent>
      <child>thruster1</child>
      <axis>
        <xyz>0 0 -1</xyz>
      </axis>
    </joint>

    <joint name="thruster2_joint" type="revolute">
      <parent>base_link</parent>
      <child>thruster2</child>
      <axis>
        <xyz>0 0 -1</xyz>
      </axis>
    </joint>

    <joint name="thruster3_joint" type="revolute">
      <parent>base_link</parent>
      <child>thruster3</child>
      <axis>
        <xyz>0 0 -1</xyz>
      </axis>
    </joint>

    <joint name="thruster4_joint" type="revolute">
      <parent>base_link</parent>
      <child>thruster4</child>
      <axis>
        <xyz>0 0 -1</xyz>
      </axis>
    </joint>

    <joint name="thruster5_joint" type="revolute">
      <parent>base_link</parent>
      <child>thruster5</child>
      <axis>
        <xyz>0 0 -1</xyz>
      </axis>
    </joint>

    <joint name="thruster6_joint" type="revolute">
      <parent>base_link</parent>
      <child>thruster6</child>
      <axis>
        <xyz>0 0 -1</xyz>
      </axis>
    </joint>

    <joint name="thruster7_joint" type="revolute">
      <parent>base_link</parent>
      <child>thruster7</child>
      <axis>
        <xyz>0 0 -1</xyz>
      </axis>
    </joint>

    <joint name="thruster8_joint" type="revolute">
      <parent>base_link</parent>
      <child>thruster8</child>
      <axis>
        <xyz>0 0 -1</xyz>
      </axis>
    </joint>

    <plugin
        filename="gz-sim-thruster-system"
        name="gz::sim::systems::Thruster">
      <namespace>bluerov2_heavy</namespace>
      <joint_name>thruster1_joint</joint_name>
      <thrust_coefficient>@thrust_coefficient</thrust_coefficient>
      <fluid_density>@fluid_density</fluid_density>
      <propeller_diameter>@propeller_diameter</propeller_diameter>
      <velocity_control>true</velocity_control>
      <use_angvel_cmd>@use_angvel_cmd</use_angvel_cmd>
    </plugin>

    <plugin
        filename="gz-sim-thruster-system"
        name="gz::sim::systems::Thruster">
      <namespace>bluerov2_heavy</namespace>
      <joint_name>thruster2_joint</joint_name>
      <thrust_coefficient>@thrust_coefficient</thrust_coefficient>
      <fluid_density>@fluid_density</fluid_density>
      <propeller_diameter>@propeller_diameter</propeller_diameter>
      <velocity_control>true</velocity_control>
      <use_angvel_cmd>@use_angvel_cmd</use_angvel_cmd>
    </plugin>

    <plugin
        filename="gz-sim-thruster-system"
        name="gz::sim::systems::Thruster">
      <namespace>bluerov2_heavy</namespace>
      <joint_name>thruster3_joint</joint_name>
      <!-- Reverse spin to balance torque -->
      <thrust_coefficient>-@thrust_coefficient</thrust_coefficient>
      <fluid_density>@fluid_density</fluid_density>
      <propeller_diameter>@propeller_diameter</propeller_diameter>
      <velocity_control>true</velocity_control>
      <use_angvel_cmd>@use_angvel_cmd</use_angvel_cmd>
    </plugin>

    <plugin
        filename="gz-sim-thruster-system"
        name="gz::sim::systems::Thruster">
      <namespace>bluerov2_heavy</namespace>
      <joint_name>thruster4_joint</joint_name>
      <!-- Reverse spin to balance torque -->
      <thrust_coefficient>-@thrust_coefficient</thrust_coefficient>
      <fluid_density>@fluid_density</fluid_density>
      <propeller_diameter>@propeller_diameter</propeller_diameter>
      <velocity_control>true</velocity_control>
      <use_angvel_cmd>@use_angvel_cmd</use_angvel_cmd>
    </plugin>

    <plugin
        filename="gz-sim-thruster-system"
        name="gz::sim::systems::Thruster">
      <namespace>bluerov2_heavy</namespace>
      <joint_name>thruster5_joint</joint_name>
      <thrust_coefficient>@thrust_coefficient</thrust_coefficient>
      <fluid_density>@fluid_density</fluid_density>
      <propeller_diameter>@propeller_diameter</propeller_diameter>
      <velocity_control>true</velocity_control>
      <use_angvel_cmd>@use_angvel_cmd</use_angvel_cmd>
    </plugin>

    <plugin
        filename="gz-sim-thruster-system"
        name="gz::sim::systems::Thruster">
      <namespace>bluerov2_heavy</namespace>
      <joint_name>thruster6_joint</joint_name>
      <!-- Reverse spin to balance torque -->
      <thrust_coefficient>-@thrust_coefficient</thrust_coefficient>
      <fluid_density>@fluid_density</fluid_density>
      <propeller_diameter>@propeller_diameter</propeller_diameter>
      <velocity_control>true</velocity_control>
      <use_angvel_cmd>@use_angvel_cmd</use_angvel_cmd>
    </plugin>

    <plugin
        filename="gz-sim-thruster-system"
        name="gz::sim::systems::Thruster">
      <namespace>bluerov2_heavy</namespace>
      <joint_name>thruster7_joint</joint_name>
      <!-- Reverse spin to balance torque -->
      <thrust_coefficient>-@thrust_coefficient</thrust_coefficient>
      <fluid_density>@fluid_density</fluid_density>
      <propeller_diameter>@propeller_diameter</propeller_diameter>
      <velocity_control>true</velocity_control>
      <use_angvel_cmd>@use_angvel_cmd</use_angvel_cmd>
    </plugin>

    <plugin
        filename="gz-sim-thruster-system"
        name="gz::sim::systems::Thruster">
      <namespace>bluerov2_heavy</namespace>
      <joint_name>thruster8_joint</joint_name>
      <thrust_coefficient>@thrust_coefficient</thrust_coefficient>
      <fluid_density>@fluid_density</fluid_density>
      <propeller_diameter>@propeller_diameter</propeller_diameter>
      <velocity_control>true</velocity_control>
      <use_angvel_cmd>@use_angvel_cmd</use_angvel_cmd>
    </plugin>

    <plugin name="ArduPilotPlugin" filename="libArduPilotPlugin.so">
      <!-- Port settings -->
      <fdm_addr>127.0.0.1</fdm_addr>
      <fdm_port_in>9002</fdm_port_in>
      <connectionTimeoutMaxCount>5</connectionTimeoutMaxCount>
      <lock_step>1</lock_step>

      <!-- Transform from the Gazebo body frame (x-forward, y-left, z-up)
           to the ArduPilot body frame (x-forward, y-right, z-down) -->
      <modelXYZToAirplaneXForwardZDown>0 0 0 @d180 0 0</modelXYZToAirplaneXForwardZDown>

      <!-- Transform from the Gazebo world frame (ENU)
           to the ArduPilot world frame (NED) -->
      <gazeboXYZToNED>0 0 0 @d180 0 @d90</gazeboXYZToNED>

      <!-- Sensors -->
      <imuName>imu_sensor</imuName>

      <!-- Thrusters -->
      <control channel="0">
        <jointName>thruster1_joint</jointName>
        <servo_min>@servo_min</servo_min>
        <servo_max>@servo_max</servo_max>
        <type>COMMAND</type>
        <cmd_topic>@thruster1_topic</cmd_topic>
        <offset>@control_offset</offset>
        <multiplier>@ccw_control_multiplier</multiplier>
      </control>
      <control channel="1">
        <jointName>thruster2_joint</jointName>
        <servo_min>@servo_min</servo_min>
        <servo_max>@servo_max</servo_max>
        <type>COMMAND</type>
        <cmd_topic>@thruster2_topic</cmd_topic>
        <offset>@control_offset</offset>
        <multiplier>@ccw_control_multiplier</multiplier>
      </control>
      <control channel="2">
        <jointName>thruster3_joint</jointName>
        <servo_min>@servo_min</servo_min>
        <servo_max>@servo_max</servo_max>
        <type>COMMAND</type>
        <cmd_topic>@thruster3_topic</cmd_topic>
        <offset>@control_offset</offset>
        <multiplier>@cw_control_multiplier</multiplier>
      </control>
      <control channel="3">
        <jointName>thruster4_joint</jointName>
        <servo_min>@servo_min</servo_min>
        <servo_max>@servo_max</servo_max>
        <type>COMMAND</type>
        <cmd_topic>@thruster4_topic</cmd_topic>
        <offset>@control_offset</offset>
        <multiplier>@cw_control_multiplier</multiplier>
      </control>
      <control channel="4">
        <jointName>thruster5_joint</jointName>
        <servo_min>@servo_min</servo_min>
        <servo_max>@servo_max</servo_max>
        <type>COMMAND</type>
        <cmd_topic>@thruster5_topic</cmd_topic>
        <offset>@control_offset</offset>
        <multiplier>@ccw_control_multiplier</multiplier>
      </control>
      <control channel="5">
        <jointName>thruster6_joint</jointName>
        <servo_min>@servo_min</servo_min>
        <servo_max>@servo_max</servo_max>
        <type>COMMAND</type>
        <cmd_topic>@thruster6_topic</cmd_topic>
        <offset>@control_offset</offset>
        <multiplier>@cw_control_multiplier</multiplier>
      </control>
      <control channel="6">
        <jointName>thruster7_joint</jointName>
        <servo_min>@servo_min</servo_min>
        <servo_max>@servo_max</servo_max>
        <type>COMMAND</type>
        <cmd_topic>@thruster7_topic</cmd_topic>
        <offset>@control_offset</offset>
        <multiplier>@cw_control_multiplier</multiplier>
      </control>
      <control channel="7">
        <jointName>thruster8_joint</jointName>
        <servo_min>@servo_min</servo_min>
        <servo_max>@servo_max</servo_max>
        <type>COMMAND</type>
        <cmd_topic>@thruster8_topic</cmd_topic>
        <offset>@control_offset</offset>
        <multiplier>@ccw_control_multiplier</multiplier>
      </control>

    </plugin>

  </model>
</sdf>